Workbook
Name mdrm_codes_df: Structure!$A$1:$E$91

Sheet MDRM codes in datasets
A1: BHC0 | C1: "Columns from dataset in zipped files"
A2: BHC2
A3: BHC5
A4: BHC9
A5: BHCB
A6: BHCK
A7: BHCP
A8: BHDM
A9: BHFN
A10: BHOD
A11: BHSP
A12: RSSD
A13: TEXC
... A15: quar

Sheet Financial
A1: MDRM Item | B1: MDRM Item left #4 | C1: Start Date | D1: End Date | E1: Short Description | F1: Description | G1: To consider | H1: to consider MDRM code | I1: Column1
A2: BHBC3368 | B2: =LEFT(A2,4) -> BHBC | C2: 37711 | D2: 2958465 | E2: AVERAGE TOTAL CONSOLIDATED ASSETS | H2: =COUNTIFS('MDRM codes in datasets'!$A$1:$A$15,B2)=1 -> FALSE
A3: BHBC3402 | B3: =LEFT(A3,4) -> BHBC | C3: 37711 | D3: 2958465 | E3: AVERAGE EARNING ASSETS | H3: =COUNTIFS('MDRM codes in datasets'!$A$1:$A$15,B3)=1 -> FALSE
A4: BHBC3516 | B4: =LEFT(A4,4) -> BHBC | C4: 37711 | D4: 2958465 | E4: AVERAGE LOANS AND LEASES (HELD FOR INVESTMENT AND HELD FOR SALE) | H4: =COUNTIFS('MDRM codes in datasets'!$A$1:$A$15,B4)=1 -> FALSE
A5: BHBC3519 | B5: =LEFT(A5,4) -> BHBC | C5: 37711 | D5: 2958465 | E5: AVERAGE EQUITY CAPITAL | H5: =COUNTIFS('MDRM codes in datasets'!$A$1:$A$15,B5)=1 -> FALSE
A6: BHBC4070 | B6: =LEFT(A6,4) -> BHBC | C6: 37711 | D6: 2958465 | E6: INCOME FROM FIDUCIARY ACTIVITIES | H6: =COUNTIFS('MDRM codes in datasets'!$A$1:$A$15,B6)=1 -> FALSE
A7: BHBC4073 | B7: =LEFT(A7,4) -> BHBC | C7: 37711 | D7: 2958465 | E7: TOTAL INTEREST EXPENSE | H7: =COUNTIFS('MDRM codes in datasets'!$A$1:$A$15,B7)=1 -> FALSE
A8: BHBC4074 | B8: =LEFT(A8,4) -> BHBC | C8: 37711 | D8: 2958465 | E8: NET INTEREST INCOME | H8: =COUNTIFS('MDRM codes in datasets'!$A$1:$A$15,B8)=1 -> FALSE
A9: BHBC4079 | B9: =LEFT(A9,4) -> BHBC | C9: 37711 | D9: 2958465 | E9: TOTAL NONINTEREST INCOME | H9: =COUNTIFS('MDRM codes in datasets'!$A$1:$A$15,B9)=1 -> FALSE
A10: BHBC4091 | B10: =LEFT(A10,4) -> BHBC | C10: 37711 | D10: 2958465 | E10: REALIZED GAINS(LOSSES) ON HTM AND AFS SECURITIES | H10: =COUNTIFS('MDRM codes in datasets'!$A$1:$A$15,B10)=1 -> FALSE
A11: BHBC4093 | B11: =LEFT(A11,4) -> BHBC | C11: 37711 | D11: 2958465 | E11: NONINTEREST EXPENSE | H11: =COUNTIFS('MDRM codes in datasets'!$A$1:$A$15,B11)=1 -> FALSE
A12: BHBC4094 | B12: =LEFT(A12,4) -> BHBC | C12: 37711 | D12: 2958465 | E12: INTEREST INCOME ON LOANS AND LEASES | H12: =COUNTIFS('MDRM codes in datasets'!$A$1:$A$15,B12)=1 -> FALSE
A13: BHBC4107 | B13: =LEFT(A13,4) -> BHBC | C13: 37711 | D13: 2958465 | E13: TOTAL INTEREST INCOME | H13: =COUNTIFS('MDRM codes in datasets'!$A$1:$A$15,B13)=1 -> FALSE
... A240: BHCA5311 | B240: =LEFT(A240,4) -> BHCA | C240: 41729 | D240: 2958465 | E240: TIER 2 CAPITAL (GREATER OF ITEM 32.A MINUS ITEM 33, OR ZERO) | H240: =COUNTIFS('MDRM codes in datasets'!$A$1:$A$15,B240)=1 -> FALSE
A241: BHCA7204 | B241: =LEFT(A241,4) -> BHCA | C241: 41729 | D241: 2958465 | E241: TIER 1 LEVERAGE RATIO (ITEM 26 DIVIDED BY ITEM 39) | G241: TRUE | H241: =COUNTIFS('MDRM codes in datasets'!$A$1:$A$15,B241)=1 -> FALSE
A242: BHCA7205 | B242: =LEFT(A242,4) -> BHCA | C242: 41729 | D242: 2958465 | E242: TOTAL CAPITAL RATIO (ITEM 35.A DIVIDED BY ITEM 40.A) | G242: TRUE | H242: =COUNTIFS('MDRM codes in datasets'!$A$1:$A$15,B242)=1 -> FALSE
A243: BHCA7206 | B243: =LEFT(A243,4) -> BHCA | C243: 41729 | D243: 2958465 | E243: TIER 1 CAPITAL RATIO (ITEM 26 DIVIDED BY ITEM 40.A) | G243: TRUE | H243: =COUNTIFS('MDRM codes in datasets'!$A$1:$A$15,B243)=1 -> FALSE
A244: BHCA8274 | B244: =LEFT(A244,4) -> BHCA | C244: 41729 | D244: 2958465 | E244: TIER 1 CAPITAL (SUM OF ITEMS 19 AND 25) | H244: =COUNTIFS('MDRM codes in datasets'!$A$1:$A$15,B244)=1 -> FALSE
A245: BHCAA223 | B245: =LEFT(A245,4) -> BHCA | C245: 41729 | D245: 2958465 | E245: TOTAL RISK-WEIGHTED ASSETS | H245: =COUNTIFS('MDRM codes in datasets'!$A$1:$A$15,B245)=1 -> FALSE
A246: BHCAA224 | B246: =LEFT(A246,4) -> BHCA | C246: 41729 | D246: 2958465 | E246: TOTAL ASSETS FOR THE LEVERAGE RATIO (ITEM 36 MINUS ITEMS 37 AND 38) | H246: =COUNTIFS('MDRM codes in datasets'!$A$1:$A$15,B246)=1 -> FALSE
A247: BHCAB530 | B247: =LEFT(A247,4) -> BHCA | C247: 41729 | D247: 2958465 | E247: ACCUMULATED OTHER COMPREHENSIVE INCOME (AOCI) | H247: =COUNTIFS('MDRM codes in datasets'!$A$1:$A$15,B247)=1 -> FALSE
A248: BHCAB596 | B248: =LEFT(A248,4) -> BHCA | C248: 41729 | D248: 2958465 | E248: OTHER DEDUCTIONS FROM (ADDITIONS TO) ASSETS FOR LEVERAGE RATIO PURPOSES | H248: =COUNTIFS('MDRM codes in datasets'!$A$1:$A$15,B248)=1 -> FALSE
A249: BHCAH036 | B249: =LEFT(A249,4) -> BHCA | C249: 42643 | D249: 2958465 | E249: ADVANCED APPROACHES HOLDING COMPANIES ONLY: SUPPLEMENTARY LEVERAGE RATIO (FROM FFIEC 101 SCHEDULE A, TABLE 2, ITEM 2.22) | H249: =COUNTIFS('MDRM codes in datasets'!$A$1:$A$15,B249)=1 -> FALSE
A250: BHCAH311 | B250: =LEFT(A250,4) -> BHCA | C250: 42460 | D250: 2958465 | E250: INSTITUTION-SPECIFIC CAPITAL BUFFER NECESSARY TO AVOID LIMITATIONS ON DISTRIBUTIONS AND DISCRETIONARY BONUS PAYMENTS: CAPTIAL CONSERVATION BUFFER | G250: TRUE | H250: =COUNTIFS('MDRM codes in datasets'!$A$1:$A$15,B250)=1 -> FALSE
A251: BHCAH312 | B251: =LEFT(A251,4) -> BHCA | C251: 42460 | D251: 44104 | E251: INSTITUTION-SPECIFIC CAPITAL BUFFER NECESSARY TO AVOID LIMITATIONS ON DISTRIBUTIONS AND DISCRETIONARY BONUS PAYMENTS: (AAHC COMPANIES THAT EXIT PARALLEL RUN ONLY) TOT APP CAP BUFFER | H251: =COUNTIFS('MDRM codes in datasets'!$A$1:$A$15,B251)=1 -> FALSE
A252: BHCAH313 | B252: =LEFT(A252,4) -> BHCA | C252: 42460 | D252: 2958465 | E252: ELIGIBLE RETAINED INCOME | H252: =COUNTIFS('MDRM codes in datasets'!$A$1:$A$15,B252)=1 -> FALSE
A253: BHCAH314 | B253: =LEFT(A253,4) -> BHCA | C253: 42460 | D253: 2958465 | E253: DISTRIBUTIONS AND DISCRETIONARY BONUS PAYMENTS DURING THE QUARTER | H253: =COUNTIFS('MDRM codes in datasets'!$A$1:$A$15,B253)=1 -> FALSE
A254: BHCAJJ29 | B254: =LEFT(A254,4) -> BHCA | C254: 43555 | D254: 2958465 | E254: TO BE COMPLETED ONLY BY INST THAT HAVE ADOPTED ASU 2016-13: DOES YOUR INSTITUTION HAVE A CECL TRANSITION ELECTION IN EFFECT AS OF THE QTR-END REPORT DATE? ("1" FOR YES; ENTER "0" FOR NO.) | H254: =COUNTIFS('MDRM codes in datasets'!$A$1:$A$15,B254)=1 -> FALSE
A255: BHCAKW00 | B255: =LEFT(A255,4) -> BHCA | C255: 43555 | D255: 2958465 | E255: RETAINED EARNINGS | H255: =COUNTIFS('MDRM codes in datasets'!$A$1:$A$15,B255)=1 -> FALSE
A256: BHCAKW03 | B256: =LEFT(A256,4) -> BHCA | C256: 43555 | D256: 2958465 | E256: AVERAGE TOTAL CONSOLIDATED ASSETS | H256: =COUNTIFS('MDRM codes in datasets'!$A$1:$A$15,B256)=1 -> FALSE
A257: BHCAKX77 | B257: =LEFT(A257,4) -> BHCA | C257: 43921 | D257: 2958465 | E257: Trading assets and trading liabilities (Schedule HC-R(I), sum of items 5 and 15). Report as a dollar amount in Column A and as a percentage of total assets (item 32 above) (5% limit) in Column B | H257: =COUNTIFS('MDRM codes in datasets'!$A$1:$A$15,B257)=1 -> FALSE
A258: BHCAKX78 | B258: =LEFT(A258,4) -> BHCA | C258: 43921 | D258: 2958465 | E258: PERCENTAGE: Trading assets and trading liabilities (Schedule HC-R(I), sum of items 5 and 15). Report as a dollar amount in Column A and as a percentage of total assets (item 32 above) (5% limit) in Column B | H258: =COUNTIFS('MDRM codes in datasets'!$A$1:$A$15,B258)=1 -> FALSE
A259: BHCAKX79 | B259: =LEFT(A259,4) -> BHCA | C259: 43921 | D259: 2958465 | E259: Unused portion of conditionally cancellable commitments | H259: =COUNTIFS('MDRM codes in datasets'!$A$1:$A$15,B259)=1 -> FALSE
A260: BHCAKX80 | B260: =LEFT(A260,4) -> BHCA | C260: 43921 | D260: 2958465 | E260: Securities lent and borrowed (Schedule HC-L, sum of items 6.a and 6.b) | H260: =COUNTIFS('MDRM codes in datasets'!$A$1:$A$15,B260)=1 -> FALSE
A261: BHCAKX81 | B261: =LEFT(A261,4) -> BHCA | C261: 43921 | D261: 2958465 | E261: Other off-balance sheet exposures | H261: =COUNTIFS('MDRM codes in datasets'!$A$1:$A$15,B261)=1 -> FALSE
A262: BHCAKX82 | B262: =LEFT(A262,4) -> BHCA | C262: 43921 | D262: 2958465 | E262: Total off-balance sheet exposures (sum of items 34.a through 34.c) Report as a dollar amount in Column A and as a percentage of total assets (item 32 above) (25% limit) in Column B | H262: =COUNTIFS('MDRM codes in datasets'!$A$1:$A$15,B262)=1 -> FALSE
... A289: BHCAP742 | B289: =LEFT(A289,4) -> BHCA | C289: 41729 | D289: 2958465 | E289: COMMON STOCK PLUS RELATED SURPLUS, NET OF TREASURY STOCK AND UNEARNED EMPLOYEE STOCK OWNERSHIP PLAN (ESOP) SHARES | H289: =COUNTIFS('MDRM codes in datasets'!$A$1:$A$15,B289)=1 -> FALSE
A290: BHCAP793 | B290: =LEFT(A290,4) -> BHCA | C290: 41729 | D290: 2958465 | E290: COMMON EQUITY TIER 1 CAPITAL RATIO (ITEM 19 DIVIDED BY ITEM 40.A) | G290: TRUE | H290: =COUNTIFS('MDRM codes in datasets'!$A$1:$A$15,B290)=1 -> FALSE
A291: BHCAP838 | B291: =LEFT(A291,4) -> BHCA | C291: 41729 | D291: 2958465 | E291: AOCI OPT-OUT ELECTION (ENTER "1" FOR YES; ENTER "0" FOR NO.) | H291: =COUNTIFS('MDRM codes in datasets'!$A$1:$A$15,B291)=1 -> FALSE
A292: BHCAP839 | B292: =LEFT(A292,4) -> BHCA | C292: 41729 | D292: 2958465 | E292: COMMON EQUITY TIER 1 MINORITY INTEREST INCLUDABLE IN COMMON EQUITY TIER 1 CAPITAL | H292: =COUNTIFS('MDRM codes in datasets'!$A$1:$A$15,B292)=1 -> FALSE
...

Sheet Structure
A1: MDRM Item | B1: MDRM Item left #4 | C1: Item Name | D1: description | E1: to consider | F1: to consider MDRM code
A2: RSSD4087 | B2: =LEFT(A2,4) -> RSSD | C2: ENTITY'S WORLD WIDE WEB ADDRESS | F2: =COUNTIFS('MDRM codes in datasets'!$A$1:$A$15,B2)=1 -> TRUE
A3: RSSD6191 | B3: =LEFT(A3,4) -> RSSD | C3: ENTITY TAX ID NUMBER | F3: =COUNTIFS('MDRM codes in datasets'!$A$1:$A$15,B3)=1 -> TRUE
A4: RSSD9001 | B4: =LEFT(A4,4) -> RSSD | C4: RSSD ID | D4: "ID_RSSD is the primary identifier on the database" "This identifier has no inherent attribute information, never changes, and is never reused. Each entity has one and only one ID_RSSD during its life cycle" "An entity ceases to exist when it is liquidated or permanently closed." "Even after its existence is completely terminated, it will remain on the database with the same ID_RSSD" | E4: TRUE | F4: =COUNTIFS('MDRM codes in datasets'!$A$1:$A$15,B4)=1 -> TRUE
A5: RSSD9005 | B5: =LEFT(A5,4) -> RSSD | C5: COUNTRY NAME | E5: TRUE | F5: =COUNTIFS('MDRM codes in datasets'!$A$1:$A$15,B5)=1 -> TRUE
A6: RSSD9007 | B6: =LEFT(A6,4) -> RSSD | C6: DATE START | D6: (JF) Date supervision started | E6: TRUE | F6: =COUNTIFS('MDRM codes in datasets'!$A$1:$A$15,B6)=1 -> TRUE
A7: RSSD9008 | B7: =LEFT(A7,4) -> RSSD | C7: DATE END | D7: (JF) Date supervision ended | E7: TRUE | F7: =COUNTIFS('MDRM codes in datasets'!$A$1:$A$15,B7)=1 -> TRUE
A8: RSSD9010 | B8: =LEFT(A8,4) -> RSSD | C8: ENTITY SHORT NAME | E8: TRUE | F8: =COUNTIFS('MDRM codes in datasets'!$A$1:$A$15,B8)=1 -> TRUE
A9: RSSD9014 | B9: =LEFT(A9,4) -> RSSD | C9: CONSERVATORSHIP CODE | F9: =COUNTIFS('MDRM codes in datasets'!$A$1:$A$15,B9)=1 -> TRUE
A10: RSSD9016 | B10: =LEFT(A10,4) -> RSSD | C10: FINANCIAL HOLDING COMPANY INDICATOR | F10: =COUNTIFS('MDRM codes in datasets'!$A$1:$A$15,B10)=1 -> TRUE
A11: RSSD9017 | B11: =LEFT(A11,4) -> RSSD | C11: LEGAL NAME | E11: TRUE | F11: =COUNTIFS('MDRM codes in datasets'!$A$1:$A$15,B11)=1 -> TRUE
A12: RSSD9028 | B12: =LEFT(A12,4) -> RSSD | C12: PHYSICAL FIRST STREET LINE | F12: =COUNTIFS('MDRM codes in datasets'!$A$1:$A$15,B12)=1 -> TRUE
A13: RSSD9029 | B13: =LEFT(A13,4) -> RSSD | C13: PHYSICAL SECOND STREET LINE | F13: =COUNTIFS('MDRM codes in datasets'!$A$1:$A$15,B13)=1 -> TRUE
A14: RSSD9030 | B14: =LEFT(A14,4) -> RSSD | C14: PHYSICAL PLACE CODE | F14: =COUNTIFS('MDRM codes in datasets'!$A$1:$A$15,B14)=1 -> TRUE
A15: RSSD9031 | B15: =LEFT(A15,4) -> RSSD | C15: COUNTRY CODE | D15: "In cases where multiple tiers exist in the organization, the "parent" institution would be the bank, bank holding company, or foreign banking organization (FBO) that is the head office of this institution, or first organization of this type which is found when tiering up from this institution." | E15: TRUE | F15: =COUNTIFS('MDRM codes in datasets'!$A$1:$A$15,B15)=1 -> TRUE
A16: RSSD9032 | B16: =LEFT(A16,4) -> RSSD | C16: FEDERAL RESERVE REGULATORY DISTRICT CODE | F16: =COUNTIFS('MDRM codes in datasets'!$A$1:$A$15,B16)=1 -> TRUE
A17: RSSD9037 | B17: =LEFT(A17,4) -> RSSD | C17: THRIFT ID | F17: =COUNTIFS('MDRM codes in datasets'!$A$1:$A$15,B17)=1 -> TRUE
A18: RSSD9038 | B18: =LEFT(A18,4) -> RSSD | C18: THRIFT HOLDING COMPANY ID | F18: =COUNTIFS('MDRM codes in datasets'!$A$1:$A$15,B18)=1 -> TRUE
A19: RSSD9039 | B19: =LEFT(A19,4) -> RSSD | C19: NCUA CHARTER ID | F19: =COUNTIFS('MDRM codes in datasets'!$A$1:$A$15,B19)=1 -> TRUE
A20: RSSD9042 | B20: =LEFT(A20,4) -> RSSD | C20: PRIMARY ABA NUMBER | F20: =COUNTIFS('MDRM codes in datasets'!$A$1:$A$15,B20)=1 -> TRUE
A21: RSSD9044 | B21: =LEFT(A21,4) -> RSSD | C21: BROAD REGULATORY CODE | D21: "A one-digit code intended to permit retrieval of major groups of entities based on their actual (not their potential) depository and legal status with regard to Regulation Y and the BHC Act. 0 = Not applicable (branches and other non head office entities). 1 = Denotes entities that are defined as banks in the Bank Holding Company Act, as amended, and implemented in the Federal Reserve's Regulation Y. Note: The statutory language used in CEBA is not employed." | E21: TRUE | F21: =COUNTIFS('MDRM codes in datasets'!$A$1:$A$15,B21)=1 -> TRUE
A22: RSSD9045 | B22: =LEFT(A22,4) -> RSSD | C22: BHC INDICATOR | F22: =COUNTIFS('MDRM codes in datasets'!$A$1:$A$15,B22)=1 -> TRUE
A23: RSSD9046 | B23: =LEFT(A23,4) -> RSSD | C23: FBO/4C9 QUALIFICATION INDICATOR | F23: =COUNTIFS('MDRM codes in datasets'!$A$1:$A$15,B23)=1 -> TRUE
A24: RSSD9047 | B24: =LEFT(A24,4) -> RSSD | C24: ORGANIZATION TYPE | D24: "A code indicating the legal structure of the organization." (JF) check site to understand the meaning of each code | E24: TRUE | F24: =COUNTIFS('MDRM codes in datasets'!$A$1:$A$15,B24)=1 -> TRUE
A25: RSSD9048 | B25: =LEFT(A25,4) -> RSSD | C25: CHARTER TYPE | D25: "type of entity based on either: The legal documents issued by the chartering or licensing authority or other documents of formation -OR- The generally accepted common name that summarizes the characteristics and business activities of the entity when a formal charter is not issued." (JF) check site to understand the meaning of each code | E25: TRUE | F25: =COUNTIFS('MDRM codes in datasets'!$A$1:$A$15,B25)=1 -> TRUE
A26: RSSD9049 | B26: =LEFT(A26,4) -> RSSD | C26: FHLBS MEMBERSHIP INDICATOR | F26: =COUNTIFS('MDRM codes in datasets'!$A$1:$A$15,B26)=1 -> TRUE
A27: RSSD9050 | B27: =LEFT(A27,4) -> RSSD | C27: FDIC CERTIFICATE ID | F27: =COUNTIFS('MDRM codes in datasets'!$A$1:$A$15,B27)=1 -> TRUE
A28: RSSD9052 | B28: =LEFT(A28,4) -> RSSD | C28: COMMENCEMENT OF EXISTENCE | D28: "The date on which the entity came into existence, e.g., the date on its papers of incorporation or formation document, or the date on which it was granted a license" | E28: TRUE | F28: =COUNTIFS('MDRM codes in datasets'!$A$1:$A$15,B28)=1 -> TRUE
A29: RSSD9053 | B29: =LEFT(A29,4) -> RSSD | C29: FINAL DAY OF EXISTENCE | D29: "The last full day that the entity existed." | E29: TRUE | F29: =COUNTIFS('MDRM codes in datasets'!$A$1:$A$15,B29)=1 -> TRUE
A30: RSSD9054 | B30: =LEFT(A30,4) -> RSSD | C30: DATE OF FISCAL YEAR END | F30: =COUNTIFS('MDRM codes in datasets'!$A$1:$A$15,B30)=1 -> TRUE
A31: RSSD9055 | B31: =LEFT(A31,4) -> RSSD | C31: OCC CHARTER ID | F31: =COUNTIFS('MDRM codes in datasets'!$A$1:$A$15,B31)=1 -> TRUE
A32: RSSD9056 | B32: =LEFT(A32,4) -> RSSD | C32: SEC REPORTING STATUS | D32: (JF) codes referring if securities are traded or not | F32: =COUNTIFS('MDRM codes in datasets'!$A$1:$A$15,B32)=1 -> TRUE
A33: RSSD9059 | B33: =LEFT(A33,4) -> RSSD | C33: FINANCIAL SUBSIDIARY HOLDER | D33: (JF) It shows whether a bank is doing extra financial activities (like investment services or insurance) through a special company it owns, called a financial subsidiary. | E33: TRUE | F33: =COUNTIFS('MDRM codes in datasets'!$A$1:$A$15,B33)=1 -> TRUE
A34: RSSD9060 | B34: =LEFT(A34,4) -> RSSD | C34: FUNCTIONAL REGULATOR | F34: =COUNTIFS('MDRM codes in datasets'!$A$1:$A$15,B34)=1 -> TRUE
A35: RSSD9061 | B35: =LEFT(A35,4) -> RSSD | C35: REASON FOR TERMINATION OF AN ENTITY | D35: "A code for the circumstances under which an entity ceased to exist or an indicator that an entity failed but remained open" | E35: TRUE | F35: =COUNTIFS('MDRM codes in datasets'!$A$1:$A$15,B35)=1 -> TRUE
A36: RSSD9101 | B36: =LEFT(A36,4) -> RSSD | C36: DOMESTIC INDICATOR | F36: =COUNTIFS('MDRM codes in datasets'!$A$1:$A$15,B36)=1 -> TRUE
A37: RSSD9130 | B37: =LEFT(A37,4) -> RSSD | C37: CITY/TOWN TEXT NAME | F37: =COUNTIFS('MDRM codes in datasets'!$A$1:$A$15,B37)=1 -> TRUE
A38: RSSD9132 | B38: =LEFT(A38,4) -> RSSD | C38: PRIMARY ACTIVITY CODE | D38: "A five or six-digit North American Industry Classification System (NAICS) Code value that best describes the primary activity conducted by an entity. A full description of all NAICS codes may be found at the U.S. Census Bureau's website at http://www.census.gov/epcd/www/naics.html" | E38: TRUE | F38: =COUNTIFS('MDRM codes in datasets'!$A$1:$A$15,B38)=1 -> TRUE
A39: RSSD9138 | B39: =LEFT(A39,4) -> RSSD | C39: FINANCIAL SUBSIDIARY INDICATOR | F39: =COUNTIFS('MDRM codes in datasets'!$A$1:$A$15,B39)=1 -> TRUE
A40: RSSD9146 | B40: =LEFT(A40,4) -> RSSD | C40: BANK COUNT | F40: =COUNTIFS('MDRM codes in datasets'!$A$1:$A$15,B40)=1 -> TRUE
...
